Workbook

Sheet README
B2: FLEET RENTAL PRICING — 2026 RATE CARD
B3: Market: Sri Lanka | Currency: LKR | Fleet Size: 518 units
B5: Purpose | C5: Internal rate-card workbook used to quote customers for daily / hourly / monthly rental of our machinery fleet.
B6: Pricing strategy | C6: Competitive but not cheapest — positioned ~15–20% below SLLDC official government rates and in line with private operators in Colombo, Gampaha, Kandy, Kurunegala.
B7: Wet rate | C7: INCLUDES fuel + operator + normal maintenance. Recommended for clients without trained operators.
B8: Dry rate | C8: Machine ONLY. Fuel, operator, lubricants, toll and food paid by client. Recommended for contractors with own crew.
B9: Daily rate | C9: Minimum billable 4 working hours per day. Derived as Hourly × 4 × 0.95 (5% volume discount).
B10: Monthly rate | C10: Minimum billable 120 working hours per month. Derived as Hourly × 120 × 0.85 (15% volume discount). Extra hours billed at Hourly rate.
B11: Age adjustment | C11: Rate declines with age: 2020+ = 100%, 2015–19 = 92%, 2010–14 = 82%, 2005–09 = 72%, 2000–04 = 65%, pre-2000 = 58%. Applied on top of base rate.
B12: Excavator size | C12: Separate multiplier by model (e.g. PC30 = 0.55×, PC200 = 1.00×, R330 = 1.30×).
B13: Client extras | C13: Trailer one-way, toll, fines, operator meals & lodging charged at cost. 15-day advance payment standard.
B14: VAT | C14: Add 18% VAT on all rates (standard SL rate 2026).
B16: Workbook sheets
B17: 1. README | C17: This page.
B18: 2. Rate Card | C18: Base hourly Wet/Dry rate per category + age factors (editable inputs in blue).
B19: 3. Fleet Pricing | C19: Every single unit (518) with calculated 2026 Dry/Wet hourly, daily (min 4h), monthly (min 120h) rates.
B20: 4. Market Research | C20: Competitor prices gathered from Sri Lankan & Indian rental portals (SLLDC, wedabima, krearthmovers, petersequipment, ikman).
B21: 5. Summary by Category | C21: Fleet count & average monthly wet revenue potential per category.
B23: Prepared | C23: April 2026 — All prices in LKR, exclusive of VAT.
B25: NEW SHEETS (v2 — engineering)
B26: 6. Engineering Assumptions | C26: All inputs: diesel price, operator rate, fuel consumption per category, PM/repair base costs, new unit prices, service life, age multipliers, consumable prices.
B27: 7. Engineering Cost | C27: Per-unit hourly cost build-up: Fuel + Operator + PM + Major repair + Overhead + 20% profit = suggested WET rate. Compare against current Fleet Pricing.
B28: 8. Maintenance & Repair | C28: Monthly spend forecast per unit (120 hrs): fuel, operator, PM, major repair, totals with overhead.
B29: 9. Replacement Analysis | C29: Every unit scored KEEP / MONITOR / REPLACE based on age, repair-to-revenue ratio, estimated 2026 resale value, and brand-new 2026 price.
B30: 10. Replacement Summary | C30: Category rollup — how many to KEEP / MONITOR / REPLACE, total CAPEX for new equipment, total resale from retiring old units.
B32: Key inputs given (Apr 2026)
B33: Operator rate | C33: Rs. 650 / hour • Minimum monthly salary Rs. 78,000
B34: Gross profit target | C34: 20% on total cost
B35: Overhead | C35: 15% of direct cost (yard, admin, insurance, transport, depreciation recovery)
B36: Diesel (CPC Auto Diesel) | C36: Rs. 382 / litre (March 2026 CPC)
B37: Min working hours | C37: 120 / month • 4 / day
B39: CHANGELOG — v3 rate engineering
B40: Issue identified | C40: Previous rates (v2) sat below engineering cost floor — we were earning less than the 20% target profit on many units.
B41: Fix (v3) | C41: Rate Card now shows Market LOW / MID / HIGH for each category and derives the recommended rate via formula: MAX(Engineering Floor, LOW × 1.10) capped at HIGH × 0.88.
B42: Outcome | C42: New rates sit in the upper-mid of the market — above bottom-feeders, below SLLDC government ceiling. Typical increase +25–40%.
B43: If the cell in column G (Eng. Floor) on Rate Card turns red | C43: It means even the market HIGH price × 0.88 won't cover cost + 20% profit. Either we must run at lower margin for that category, or stop renting it out.
B45: CHANGELOG — v4 portable equipment
B46: New sheet added | C46: "Portable Equipment Rates" (sheet 3) — capacity-wise daily hire rates for generators, air compressors, poker/concrete vibrators, submersible pumps (1"–6"), engine water pumps (2"/3"/4"), rotary hammers, circular saws, angle grinders, plate compactor, power trowel and welding plant.
B47: Basis | C47: WET = fuel/operator/consumables included; DRY = bare hire. Per-day billing, minimum 1 day. 36 line items across 10 categories. Excludes 18% VAT & transport.
B48: Market sources | C48: Sri Lankan rental market, May–Jun 2026: Peters Equipment (petersequipment.lk) published day-rates; surplus.lk and wedabima.com availability. Generators Rs.4,000–12,000/day by kVA; Rotary Hammer SDS Rs.3,000; Demolition Breaker Rs.4,000; Tamping Rammer Rs.3,500; drills Rs.250–500.
...

Sheet Rate Card
A1: 2026 RATE CARD — Engineering-Derived Hourly Rates
A2: Each rate is computed from three drivers: Market LOW, Market HIGH, and Engineering Cost + 20% profit. Recommended Wet = MAX(Engineering Floor, Market LOW × 1.10) capped at Market HIGH × 0.88. Recommended Dry = Wet × Dry ratio (industry convention). Blue cells = editable inputs.
A4: # | B4: Category | C4: Market LOW (wet) | D4: Market MID (wet) | E4: Market HIGH (wet) | F4: Eng. Cost / h (age-5) | G4: Eng. Floor (+20% profit) | H4: Positioning rule | I4: Recommended WET (/h) | J4: Dry ratio (blue = editable) | K4: Recommended DRY (/h) | L4: Wet : Dry ratio | M4: % above LOW | N4: % below HIGH | O4: Source / note
A5: 1 | B5: Backhoe Loader | C5: 2500 | D5: 3500 | E5: 6050 | F5: ='Engineering Assumptions'!$C$18*'Engineering Assumptions'!$B$5+'Engineering Assumptions'!$B$8+'Engineering Assumptions'!$D$18*1+'Engineering Assumptions'!$E$18*0.3 -> 2997 | G5: =F5*(1+'Engineering Assumptions'!$B$10)*(1+'Engineering Assumptions'!$B$11) -> 4135.86 | H5: MAX(Eng. Floor, LOW×1.10) capped at HIGH×0.88 | I5: =MROUND(MIN(MAX(G5,C5*1.1),E5*0.88),50) -> 4150 | J5: 0.48 | K5: =MROUND(I5*J5,50) -> 2000 | L5: =K5/I5 -> 0.48192771 | M5: =(I5-C5)/C5 -> 0.66 | N5: =(E5-I5)/E5 -> 0.31404959 | O5: LOW: Small private, Wedabima • HIGH: SLLDC JCB 3CX wet
A6: 2 | B6: Wheel Loader | C6: 5000 | D6: 8500 | E6: 15760 | F6: ='Engineering Assumptions'!$C$19*'Engineering Assumptions'!$B$5+'Engineering Assumptions'!$B$8+'Engineering Assumptions'!$D$19*1+'Engineering Assumptions'!$E$19*0.3 -> 6110 | G6: =F6*(1+'Engineering Assumptions'!$B$10)*(1+'Engineering Assumptions'!$B$11) -> 8431.8 | H6: MAX(Eng. Floor, LOW×1.10) capped at HIGH×0.88 | I6: =MROUND(MIN(MAX(G6,C6*1.1),E6*0.88),50) -> 8450 | J6: 0.45 | K6: =MROUND(I6*J6,50) -> 3800 | L6: =K6/I6 -> 0.44970414 | M6: =(I6-C6)/C6 -> 0.69 | N6: =(E6-I6)/E6 -> 0.46383249 | O6: LOW: Used private • HIGH: SLLDC Doosan Mega 250
A7: 3 | B7: Truck Mixer | C7: 3500 | D7: 4500 | E7: 5500 | F7: ='Engineering Assumptions'!$C$20*'Engineering Assumptions'!$B$5+'Engineering Assumptions'!$B$8+'Engineering Assumptions'!$D$20*1+'Engineering Assumptions'!$E$20*0.3 -> 3628 | G7: =F7*(1+'Engineering Assumptions'!$B$10)*(1+'Engineering Assumptions'!$B$11) -> 5006.64 | H7: MAX(Eng. Floor, LOW×1.10) capped at HIGH×0.88 | I7: =MROUND(MIN(MAX(G7,C7*1.1),E7*0.88),50) -> 4850 | J7: 0.5 | K7: =MROUND(I7*J7,50) -> 2450 | L7: =K7/I7 -> 0.50515464 | M7: =(I7-C7)/C7 -> 0.38571429 | N7: =(E7-I7)/E7 -> 0.11818182 | O7: LOW: TATA mixer private • HIGH: Large private operators
A8: 4 | B8: Self Loader Mixer | C8: 4500 | D8: 5200 | E8: 6000 | F8: ='Engineering Assumptions'!$C$21*'Engineering Assumptions'!$B$5+'Engineering Assumptions'!$B$8+'Engineering Assumptions'!$D$21*1+'Engineering Assumptions'!$E$21*0.3 -> 4062 | G8: =F8*(1+'Engineering Assumptions'!$B$10)*(1+'Engineering Assumptions'!$B$11) -> 5605.56 | H8: MAX(Eng. Floor, LOW×1.10) capped at HIGH×0.88 | I8: =MROUND(MIN(MAX(G8,C8*1.1),E8*0.88),50) -> 5300 | J8: 0.5 | K8: =MROUND(I8*J8,50) -> 2650 | L8: =K8/I8 -> 0.5 | M8: =(I8-C8)/C8 -> 0.17777778 | N8: =(E8-I8)/E8 -> 0.11666667 | O8: LOW: FIORI/Ajax private • HIGH: Large operators
A9: 5 | B9: Static Roller | C9: 2500 | D9: 3500 | E9: 5230 | F9: ='Engineering Assumptions'!$C$22*'Engineering Assumptions'!$B$5+'Engineering Assumptions'!$B$8+'Engineering Assumptions'!$D$22*1+'Engineering Assumptions'!$E$22*0.3 -> 4029 | G9: =F9*(1+'Engineering Assumptions'!$B$10)*(1+'Engineering Assumptions'!$B$11) -> 5560.02 | H9: MAX(Eng. Floor, LOW×1.10) capped at HIGH×0.88 | I9: =MROUND(MIN(MAX(G9,C9*1.1),E9*0.88),50) -> 4600 | J9: 0.5 | K9: =MROUND(I9*J9,50) -> 2300 | L9: =K9/I9 -> 0.5 | M9: =(I9-C9)/C9 -> 0.84 | N9: =(E9-I9)/E9 -> 0.12045889 | O9: LOW: Private 10T • HIGH: SLLDC HAMM HD12vv
A10: 6 | B10: Vibrating Roller | C10: 3000 | D10: 4000 | E10: 5000 | F10: ='Engineering Assumptions'!$C$23*'Engineering Assumptions'!$B$5+'Engineering Assumptions'!$B$8+'Engineering Assumptions'!$D$23*1+'Engineering Assumptions'!$E$23*0.3 -> 2812 | G10: =F10*(1+'Engineering Assumptions'!$B$10)*(1+'Engineering Assumptions'!$B$11) -> 3880.56 | H10: MAX(Eng. Floor, LOW×1.10) capped at HIGH×0.88 | I10: =MROUND(MIN(MAX(G10,C10*1.1),E10*0.88),50) -> 3900 | J10: 0.5 | K10: =MROUND(I10*J10,50) -> 1950 | L10: =K10/I10 -> 0.5 | M10: =(I10-C10)/C10 -> 0.3 | N10: =(E10-I10)/E10 -> 0.22 | O10: LOW: BOMAG private • HIGH: Large private 10T
A11: 7 | B11: Pneumatic Roller | C11: 3000 | D11: 3800 | E11: 4500 | F11: ='Engineering Assumptions'!$C$24*'Engineering Assumptions'!$B$5+'Engineering Assumptions'!$B$8+'Engineering Assumptions'!$D$24*1+'Engineering Assumptions'!$E$24*0.3 -> 3605 | G11: =F11*(1+'Engineering Assumptions'!$B$10)*(1+'Engineering Assumptions'!$B$11) -> 4974.9 | H11: MAX(Eng. Floor, LOW×1.10) capped at HIGH×0.88 | I11: =MROUND(MIN(MAX(G11,C11*1.1),E11*0.88),50) -> 3950 | J11: 0.5 | K11: =MROUND(I11*J11,50) -> 2000 | L11: =K11/I11 -> 0.50632911 | M11: =(I11-C11)/C11 -> 0.31666667 | N11: =(E11-I11)/E11 -> 0.12222222 | O11: LOW: Private Sakai/Dynapac • HIGH: Premium operators
A12: 8 | B12: Motor Grader | C12: 7000 | D12: 8500 | E12: 11000 | F12: ='Engineering Assumptions'!$C$25*'Engineering Assumptions'!$B$5+'Engineering Assumptions'!$B$8+'Engineering Assumptions'!$D$25*1+'Engineering Assumptions'!$E$25*0.3 -> 6980 | G12: =F12*(1+'Engineering Assumptions'!$B$10)*(1+'Engineering Assumptions'!$B$11) -> 9632.4 | H12: MAX(Eng. Floor, LOW×1.10) capped at HIGH×0.88 | I12: =MROUND(MIN(MAX(G12,C12*1.1),E12*0.88),50) -> 9650 | J12: 0.45 | K12: =MROUND(I12*J12,50) -> 4350 | L12: =K12/I12 -> 0.4507772 | M12: =(I12-C12)/C12 -> 0.37857143 | N12: =(E12-I12)/E12 -> 0.12272727 | O12: LOW: Private used CAT • HIGH: Premium/SLLDC class
A13: 9 | B13: Skid Steer | C13: 2000 | D13: 2500 | E13: 3060 | F13: ='Engineering Assumptions'!$C$26*'Engineering Assumptions'!$B$5+'Engineering Assumptions'!$B$8+'Engineering Assumptions'!$D$26*1+'Engineering Assumptions'!$E$26*0.3 -> 2589 | G13: =F13*(1+'Engineering Assumptions'!$B$10)*(1+'Engineering Assumptions'!$B$11) -> 3572.82 | H13: MAX(Eng. Floor, LOW×1.10) capped at HIGH×0.88 | I13: =MROUND(MIN(MAX(G13,C13*1.1),E13*0.88),50) -> 2700 | J13: 0.5 | K13: =MROUND(I13*J13,50) -> 1350 | L13: =K13/I13 -> 0.5 | M13: =(I13-C13)/C13 -> 0.35 | N13: =(E13-I13)/E13 -> 0.11764706 | O13: LOW: Small private • HIGH: SLLDC Bobcat
A14: 10 | B14: Asphalt Paver | C14: 7000 | D14: 8500 | E14: 10000 | F14: ='Engineering Assumptions'!$C$27*'Engineering Assumptions'!$B$5+'Engineering Assumptions'!$B$8+'Engineering Assumptions'!$D$27*1+'Engineering Assumptions'!$E$27*0.3 -> 5822 | G14: =F14*(1+'Engineering Assumptions'!$B$10)*(1+'Engineering Assumptions'!$B$11) -> 8034.36 | H14: MAX(Eng. Floor, LOW×1.10) capped at HIGH×0.88 | I14: =MROUND(MIN(MAX(G14,C14*1.1),E14*0.88),50) -> 8050 | J14: 0.45 | K14: =MROUND(I14*J14,50) -> 3600 | L14: =K14/I14 -> 0.44720497 | M14: =(I14-C14)/C14 -> 0.15 | N14: =(E14-I14)/E14 -> 0.195 | O14: LOW: SUMITOMO private • HIGH: VOLVO premium
A15: 11 | B15: Bitumen Bowser | C15: 2500 | D15: 3200 | E15: 4000 | F15: ='Engineering Assumptions'!$C$28*'Engineering Assumptions'!$B$5+'Engineering Assumptions'!$B$8+'Engineering Assumptions'!$D$28*1+'Engineering Assumptions'!$E$28*0.3 -> 3366 | G15: =F15*(1+'Engineering Assumptions'!$B$10)*(1+'Engineering Assumptions'!$B$11) -> 4645.08 | H15: MAX(Eng. Floor, LOW×1.10) capped at HIGH×0.88 | I15: =MROUND(MIN(MAX(G15,C15*1.1),E15*0.88),50) -> 3500 | J15: 0.5 | K15: =MROUND(I15*J15,50) -> 1750 | L15: =K15/I15 -> 0.5 | M15: =(I15-C15)/C15 -> 0.4 | N15: =(E15-I15)/E15 -> 0.125 | O15: LOW: Private 4-cu • HIGH: Large insulated bowser
A16: 12 | B16: Mobile Crane | C16: 8000 | D16: 9500 | E16: 11660 | F16: ='Engineering Assumptions'!$C$29*'Engineering Assumptions'!$B$5+'Engineering Assumptions'!$B$8+'Engineering Assumptions'!$D$29*1+'Engineering Assumptions'!$E$29*0.3 -> 4954 | G16: =F16*(1+'Engineering Assumptions'!$B$10)*(1+'Engineering Assumptions'!$B$11) -> 6836.52 | H16: MAX(Eng. Floor, LOW×1.10) capped at HIGH×0.88 | I16: =MROUND(MIN(MAX(G16,C16*1.1),E16*0.88),50) -> 8800 | J16: 0.5 | K16: =MROUND(I16*J16,50) -> 4400 | L16: =K16/I16 -> 0.5 | M16: =(I16-C16)/C16 -> 0.1 | N16: =(E16-I16)/E16 -> 0.24528302 | O16: LOW: Private 25T • HIGH: SLLDC Kobelco RK250
A17: 13 | B17: Boom Truck | C17: 4000 | D17: 5000 | E17: 6610 | F17: ='Engineering Assumptions'!$C$30*'Engineering Assumptions'!$B$5+'Engineering Assumptions'!$B$8+'Engineering Assumptions'!$D$30*1+'Engineering Assumptions'!$E$30*0.3 -> 3628 | G17: =F17*(1+'Engineering Assumptions'!$B$10)*(1+'Engineering Assumptions'!$B$11) -> 5006.64 | H17: MAX(Eng. Floor, LOW×1.10) capped at HIGH×0.88 | I17: =MROUND(MIN(MAX(G17,C17*1.1),E17*0.88),50) -> 5000 | J17: 0.5 | K17: =MROUND(I17*J17,50) -> 2500 | L17: =K17/I17 -> 0.5 | M17: =(I17-C17)/C17 -> 0.25 | N17: =(E17-I17)/E17 -> 0.24357035 | O17: LOW: Califolink private • HIGH: SLLDC 17T 3T-crane
A18: 14 | B18: Prime Mover / Bed | C18: 3500 | D18: 4500 | E18: 5500 | F18: ='Engineering Assumptions'!$C$31*'Engineering Assumptions'!$B$5+'Engineering Assumptions'!$B$8+'Engineering Assumptions'!$D$31*1+'Engineering Assumptions'!$E$31*0.3 -> 6363 | G18: =F18*(1+'Engineering Assumptions'!$B$10)*(1+'Engineering Assumptions'!$B$11) -> 8780.94 | H18: MAX(Eng. Floor, LOW×1.10) capped at HIGH×0.88 | I18: =MROUND(MIN(MAX(G18,C18*1.1),E18*0.88),50) -> 4850 | J18: 0.5 | K18: =MROUND(I18*J18,50) -> 2450 | L18: =K18/I18 -> 0.50515464 | M18: =(I18-C18)/C18 -> 0.38571429 | N18: =(E18-I18)/E18 -> 0.11818182 | O18: LOW: Private HINO/TATA • HIGH: Premium lowbed operators
A19: 15 | B19: Pump Truck (Concrete) | C19: 8500 | D19: 10000 | E19: 11000 | F19: ='Engineering Assumptions'!$C$32*'Engineering Assumptions'!$B$5+'Engineering Assumptions'!$B$8+'Engineering Assumptions'!$D$32*1+'Engineering Assumptions'!$E$32*0.3 -> 6242 | G19: =F19*(1+'Engineering Assumptions'!$B$10)*(1+'Engineering Assumptions'!$B$11) -> 8613.96 | H19: MAX(Eng. Floor, LOW×1.10) capped at HIGH×0.88 | I19: =MROUND(MIN(MAX(G19,C19*1.1),E19*0.88),50) -> 9350 | J19: 0.45 | K19: =MROUND(I19*J19,50) -> 4200 | L19: =K19/I19 -> 0.44919786 | M19: =(I19-C19)/C19 -> 0.1 | N19: =(E19-I19)/E19 -> 0.15 | O19: LOW: Private Sany pump • HIGH: Premium operators
A20: 16 | B20: Double Cab (Pickup) | C20: 1200 | D20: 1500 | E20: 2000 | F20: ='Engineering Assumptions'!$C$33*'Engineering Assumptions'!$B$5+'Engineering Assumptions'!$B$8+'Engineering Assumptions'!$D$33*1+'Engineering Assumptions'!$E$33*0.3 -> 1919 | G20: =F20*(1+'Engineering Assumptions'!$B$10)*(1+'Engineering Assumptions'!$B$11) -> 2648.22 | H20: MAX(Eng. Floor, LOW×1.10) capped at HIGH×0.88 | I20: =MROUND(MIN(MAX(G20,C20*1.1),E20*0.88),50) -> 1750 | J20: 0.55 | K20: =MROUND(I20*J20,50) -> 950 | L20: =K20/I20 -> 0.54285714 | M20: =(I20-C20)/C20 -> 0.45833333 | N20: =(E20-I20)/E20 -> 0.125 | O20: LOW: Hilux long-term private • HIGH: Malkey/Lanka Rent premium
A21: 17 | B21: Van | C21: 950 | D21: 1300 | E21: 1800 | F21: ='Engineering Assumptions'!$C$34*'Engineering Assumptions'!$B$5+'Engineering Assumptions'!$B$8+'Engineering Assumptions'!$D$34*1+'Engineering Assumptions'!$E$34*0.3 -> 1702 | G21: =F21*(1+'Engineering Assumptions'!$B$10)*(1+'Engineering Assumptions'!$B$11) -> 2348.76 | H21: MAX(Eng. Floor, LOW×1.10) capped at HIGH×0.88 | I21: =MROUND(MIN(MAX(G21,C21*1.1),E21*0.88),50) -> 1600 | J21: 0.55 | K21: =MROUND(I21*J21,50) -> 900 | L21: =K21/I21 -> 0.5625 | M21: =(I21-C21)/C21 -> 0.68421053 | N21: =(E21-I21)/E21 -> 0.11111111 | O21: LOW: Liteace private • HIGH: KDH200 premium
A22: 18 | B22: Crew Cab | C22: 900 | D22: 1200 | E22: 1600 | F22: ='Engineering Assumptions'!$C$35*'Engineering Assumptions'!$B$5+'Engineering Assumptions'!$B$8+'Engineering Assumptions'!$D$35*1+'Engineering Assumptions'!$E$35*0.3 -> 1906 | G22: =F22*(1+'Engineering Assumptions'!$B$10)*(1+'Engineering Assumptions'!$B$11) -> 2630.28 | H22: MAX(Eng. Floor, LOW×1.10) capped at HIGH×0.88 | I22: =MROUND(MIN(MAX(G22,C22*1.1),E22*0.88),50) -> 1400 | J22: 0.55 | K22: =MROUND(I22*J22,50) -> 750 | L22: =K22/I22 -> 0.53571429 | M22: =(I22-C22)/C22 -> 0.55555556 | N22: =(E22-I22)/E22 -> 0.125 | O22: LOW: JMC private • HIGH: ISUZU premium
A23: 19 | B23: Single Cab | C23: 700 | D23: 1000 | E23: 1300 | F23: ='Engineering Assumptions'!$C$36*'Engineering Assumptions'!$B$5+'Engineering Assumptions'!$B$8+'Engineering Assumptions'!$D$36*1+'Engineering Assumptions'!$E$36*0.3 -> 1702 | G23: =F23*(1+'Engineering Assumptions'!$B$10)*(1+'Engineering Assumptions'!$B$11) -> 2348.76 | H23: MAX(Eng. Floor, LOW×1.10) capped at HIGH×0.88 | I23: =MROUND(MIN(MAX(G23,C23*1.1),E23*0.88),50) -> 1150 | J23: 0.55 | K23: =MROUND(I23*J23,50) -> 650 | L23: =K23/I23 -> 0.56521739 | M23: =(I23-C23)/C23 -> 0.64285714 | N23: =(E23-I23)/E23 -> 0.11538462 | O23: LOW: Tata Ace small • HIGH: Mahindra BMT premium
A24: 20 | B24: Dump Truck (Tipper) | C24: 2000 | D24: 2800 | E24: 3700 | F24: ='Engineering Assumptions'!$C$37*'Engineering Assumptions'!$B$5+'Engineering Assumptions'!$B$8+'Engineering Assumptions'!$D$37*1+'Engineering Assumptions'!$E$37*0.3 -> 3838 | G24: =F24*(1+'Engineering Assumptions'!$B$10)*(1+'Engineering Assumptions'!$B$11) -> 5296.44 | H24: MAX(Eng. Floor, LOW×1.10) capped at HIGH×0.88 | I24: =MROUND(MIN(MAX(G24,C24*1.1),E24*0.88),50) -> 3250 | J24: 0.48 | K24: =MROUND(I24*J24,50) -> 1550 | L24: =K24/I24 -> 0.47692308 | M24: =(I24-C24)/C24 -> 0.625 | N24: =(E24-I24)/E24 -> 0.12162162 | O24: LOW: Ikman monthly low • HIGH: Premium Tata LPK1618
A25: 21 | B25: Trailer | C25: 1200 | D25: 1700 | E25: 2200 | F25: ='Engineering Assumptions'!$C$38*'Engineering Assumptions'!$B$5+0+'Engineering Assumptions'!$D$38*1+'Engineering Assumptions'!$E$38*0.3 -> 71 | G25: =F25*(1+'Engineering Assumptions'!$B$10)*(1+'Engineering Assumptions'!$B$11) -> 97.98 | H25: MAX(Eng. Floor, LOW×1.10) capped at HIGH×0.88 | I25: =MROUND(MIN(MAX(G25,C25*1.1),E25*0.88),50) -> 1300 | J25: 0.95 | K25: =MROUND(I25*J25,50) -> 1250 | L25: =K25/I25 -> 0.96153846 | M25: =(I25-C25)/C25 -> 0.083333333 | N25: =(E25-I25)/E25 -> 0.40909091 | O25: LOW: Private tractor trailer • HIGH: Premium operators
A26: 22 | B26: Lorry Trailer | C26: 2000 | D26: 2600 | E26: 3200 | F26: ='Engineering Assumptions'!$C$39*'Engineering Assumptions'!$B$5+0+'Engineering Assumptions'!$D$39*1+'Engineering Assumptions'!$E$39*0.3 -> 84 | G26: =F26*(1+'Engineering Assumptions'!$B$10)*(1+'Engineering Assumptions'!$B$11) -> 115.92 | H26: MAX(Eng. Floor, LOW×1.10) capped at HIGH×0.88 | I26: =MROUND(MIN(MAX(G26,C26*1.1),E26*0.88),50) -> 2200 | J26: 0.95 | K26: =MROUND(I26*J26,50) -> 2100 | L26: =K26/I26 -> 0.95454545 | M26: =(I26-C26)/C26 -> 0.1 | N26: =(E26-I26)/E26 -> 0.3125 | O26: LOW: Private Tantri • HIGH: Premium Tantri TFB40
A27: 23 | B27: Diesel Bowser | C27: 1500 | D27: 2200 | E27: 2800 | F27: ='Engineering Assumptions'!$C$40*'Engineering Assumptions'!$B$5+'Engineering Assumptions'!$B$8+'Engineering Assumptions'!$D$40*1+'Engineering Assumptions'!$E$40*0.3 -> 2139 | G27: =F27*(1+'Engineering Assumptions'!$B$10)*(1+'Engineering Assumptions'!$B$11) -> 2951.82 | H27: MAX(Eng. Floor, LOW×1.10) capped at HIGH×0.88 | I27: =MROUND(MIN(MAX(G27,C27*1.1),E27*0.88),50) -> 2450 | J27: 0.55 | K27: =MROUND(I27*J27,50) -> 1350 | L27: =K27/I27 -> 0.55102041 | M27: =(I27-C27)/C27 -> 0.63333333 | N27: =(E27-I27)/E27 -> 0.125 | O27: LOW: Private fuel bowser • HIGH: Premium large bowser
A28: 24 | B28: Excavator | C28: 5500 | D28: 7500 | E28: 12100 | F28: ='Engineering Assumptions'!$C$41*'Engineering Assumptions'!$B$5+'Engineering Assumptions'!$B$8+'Engineering Assumptions'!$D$41*1+'Engineering Assumptions'!$E$41*0.3 -> 6916 | G28: =F28*(1+'Engineering Assumptions'!$B$10)*(1+'Engineering Assumptions'!$B$11) -> 9544.08 | H28: MAX(Eng. Floor, LOW×1.10) capped at HIGH×0.88 | I28: =MROUND(MIN(MAX(G28,C28*1.1),E28*0.88),50) -> 9550 | J28: 0.45 | K28: =MROUND(I28*J28,50) -> 4300 | L28: =K28/I28 -> 0.45026178 | M28: =(I28-C28)/C28 -> 0.73636364 | N28: =(E28-I28)/E28 -> 0.2107438 | O28: LOW: Private 20T Hyundai • HIGH: SLLDC Doosan DX200
A29: 25 | B29: Water Bowser | C29: 1800 | D29: 2300 | E29: 4940 | F29: ='Engineering Assumptions'!$C$42*'Engineering Assumptions'!$B$5+'Engineering Assumptions'!$B$8+'Engineering Assumptions'!$D$42*1+'Engineering Assumptions'!$E$42*0.3 -> 2152 | G29: =F29*(1+'Engineering Assumptions'!$B$10)*(1+'Engineering Assumptions'!$B$11) -> 2969.76 | H29: MAX(Eng. Floor, LOW×1.10) capped at HIGH×0.88 | I29: =MROUND(MIN(MAX(G29,C29*1.1),E29*0.88),50) -> 2950 | J29: 0.5 | K29: =MROUND(I29*J29,50) -> 1500 | L29: =K29/I29 -> 0.50847458 | M29: =(I29-C29)/C29 -> 0.63888889 | N29: =(E29-I29)/E29 -> 0.40283401 | O29: LOW: Private small • HIGH: SLLDC 6,000L equiv.
A30: 26 | B30: Farm Tractor | C30: 1200 | D30: 1800 | E30: 2400 | F30: ='Engineering Assumptions'!$C$43*'Engineering Assumptions'!$B$5+'Engineering Assumptions'!$B$8+'Engineering Assumptions'!$D$43*1+'Engineering Assumptions'!$E$43*0.3 -> 2330 | G30: =F30*(1+'Engineering Assumptions'!$B$10)*(1+'Engineering Assumptions'!$B$11) -> 3215.4 | H30: MAX(Eng. Floor, LOW×1.10) capped at HIGH×0.88 | I30: =MROUND(MIN(MAX(G30,C30*1.1),E30*0.88),50) -> 2100 | J30: 0.55 | K30: =MROUND(I30*J30,50) -> 1150 | L30: =K30/I30 -> 0.54761905 | M30: =(I30-C30)/C30 -> 0.75 | N30: =(E30-I30)/E30 -> 0.125 | O30: LOW: MASSEY/TAFE private • HIGH: MAHINDRA premium
A31: 27 | B31: Motor Bicycle | C31: 250 | D31: 350 | E31: 550 | F31: ='Engineering Assumptions'!$C$44*'Engineering Assumptions'!$B$5+0+'Engineering Assumptions'!$D$44*1+'Engineering Assumptions'!$E$44*0.3 -> 493.9 | G31: =F31*(1+'Engineering Assumptions'!$B$10)*(1+'Engineering Assumptions'!$B$11) -> 681.582 | H31: MAX(Eng. Floor, LOW×1.10) capped at HIGH×0.88 | I31: =MROUND(MIN(MAX(G31,C31*1.1),E31*0.88),50) -> 500 | J31: 0.6 | K31: =MROUND(I31*J31,50) -> 300 | L31: =K31/I31 -> 0.6 | M31: =(I31-C31)/C31 -> 1 | N31: =(E31-I31)/E31 -> 0.090909091 | O31: LOW: Staff rental private • HIGH: Daily hire
A32: 28 | B32: Tractor Bowser | C32: 1200 | D32: 1600 | E32: 2000 | F32: ='Engineering Assumptions'!$C$45*'Engineering Assumptions'!$B$5+'Engineering Assumptions'!$B$8+'Engineering Assumptions'!$D$45*1+'Engineering Assumptions'!$E$45*0.3 -> 2521 | G32: =F32*(1+'Engineering Assumptions'!$B$10)*(1+'Engineering Assumptions'!$B$11) -> 3478.98 | H32: MAX(Eng. Floor, LOW×1.10) capped at HIGH×0.88 | I32: =MROUND(MIN(MAX(G32,C32*1.1),E32*0.88),50) -> 1750 | J32: 0.55 | K32: =MROUND(I32*J32,50) -> 950 | L32: =K32/I32 -> 0.54285714 | M32: =(I32-C32)/C32 -> 0.45833333 | N32: =(E32-I32)/E32 -> 0.125 | O32: LOW: Private combo • HIGH: Premium combo
A33: 29 | B33: Forklift | C33: 2000 | D33: 3000 | E33: 3800 | F33: ='Engineering Assumptions'!$C$46*'Engineering Assumptions'!$B$5+'Engineering Assumptions'!$B$8+'Engineering Assumptions'!$D$46*1+'Engineering Assumptions'!$E$46*0.3 -> 2210 | G33: =F33*(1+'Engineering Assumptions'!$B$10)*(1+'Engineering Assumptions'!$B$11) -> 3049.8 | H33: MAX(Eng. Floor, LOW×1.10) capped at HIGH×0.88 | I33: =MROUND(MIN(MAX(G33,C33*1.1),E33*0.88),50) -> 3050 | J33: 0.5 | K33: =MROUND(I33*J33,50) -> 1550 | L33: =K33/I33 -> 0.50819672 | M33: =(I33-C33)/C33 -> 0.525 | N33: =(E33-I33)/E33 -> 0.19736842 | O33: LOW: Private 3T • HIGH: Premium insulated/specialist
A36: AGE DEPRECIATION APPLIED TO FLEET UNITS
A37: Year of manufacture | B37: Age factor | C37: % of base rate | D37: Rationale
A38: 2020 and newer | B38: 1 | C38: =B38 -> 1 | D38: Same as new — no discount
A39: 2015 – 2019 | B39: 0.92 | C39: =B39 -> 0.92 | D39: Light depreciation
A40: 2010 – 2014 | B40: 0.82 | C40: =B40 -> 0.82 | D40: Used but serviceable
A41: 2005 – 2009 | B41: 0.72 | C41: =B41 -> 0.72 | D41: Older unit — customer expects discount
A42: 2000 – 2004 | B42: 0.65 | C42: =B42 -> 0.65 | D42: Legacy — only for budget-sensitive clients
A43: Before 2000 / Unknown | B43: 0.58 | C43: =B43 -> 0.58 | D43: End-of-life — last resort only
...

Sheet Portable Equipment Rates
A1: 2026 PORTABLE EQUIPMENT RATES — Day-Hire, Sri Lankan Market
A2: Capacity-wise daily hire rates (Rs./day) for portable plant, surveyed from the Sri Lankan rental market (May–Jun 2026). WET = with fuel/operator/consumables; DRY = bare machine hire only. Min. billing 1 day. Rates exclude 18% VAT and transport.
A4: # | B4: Category | C4: Capacity / Size | D4: WET Rs./day | E4: DRY Rs./day | F4: Billing | G4: Min. | H4: Source / basis note
A5: 1 | B5: Generator | C5: 3–5 kVA (petrol, 1-ph) | D5: 5000 | E5: 2500 | F5: Per day | G5: 1 day | H5: Peters Equipment: 5kVA Rs.4,000 / 2-3kVA Rs.5,000 per day
A6: 2 | B6: Generator | C6: 10 kVA (diesel, 1-ph) | D6: 7000 | E6: 3500 | F6: Per day | G6: 1 day | H6: Peters Equipment 10kVA diesel Rs.6,000/day (op w/fuel basis)
A7: 3 | B7: Generator | C7: 20–25 kVA (diesel, 3-ph) | D7: 12000 | E7: 6000 | F7: Per day | G7: 1 day | H7: Peters Equipment 25kVA diesel Rs.8,000/day
A8: 4 | B8: Generator | C8: 30–50 kVA (diesel, 3-ph) | D8: 18000 | E8: 10000 | F8: Per day | G8: 1 day | H8: Peters Equipment 50kVA diesel Rs.10-12,000/day
A9: 5 | B9: Generator | C9: 60–80 kVA (soundproof) | D9: 26000 | E9: 15000 | F9: Per day | G9: 1 day | H9: Interpolated from 50kVA card + UTE/Generators.lk band
A10: 6 | B10: Generator | C10: 100–125 kVA (soundproof) | D10: 38000 | E10: 22000 | F10: Per day | G10: 1 day | H10: Generators.lk / UTE long-term construction band
A11: 7 | B11: Generator | C11: 150 kVA (soundproof) | D11: 48000 | E11: 28000 | F11: Per day | G11: 1 day | H11: Generators.lk 150kVA upper rental band
A12: 8 | B12: Air Compressor | C12: 2–3 HP (portable, electric) | D12: 2200 | E12: 1300 | F12: Per day | G12: 1 day | H12: SL hire-shop day-rate; surplus.lk "any capacity per day"
A13: 9 | B13: Air Compressor | C13: 5–7 HP (belt-drive, petrol) | D13: 3800 | E13: 2400 | F13: Per day | G13: 1 day | H13: Competitive Western-Province hire-shop day-rate
A14: 10 | B14: Air Compressor | C14: 10–15 HP (industrial) | D14: 6500 | E14: 4500 | F14: Per day | G14: 1 day | H14: Competitive Western-Province hire-shop day-rate
A15: 11 | B15: Air Compressor | C15: 185 cfm (towable diesel) | D15: 16000 | E15: 11000 | F15: Per day | G15: 1 day | H15: Towable jackhammer-feed compressor; project day-rate
A16: 12 | B16: Air Compressor | C16: 375 cfm (towable diesel) | D16: 26000 | E16: 18000 | F16: Per day | G16: 1 day | H16: Large towable diesel; project day-rate
... A40: 36 | B40: Welding Plant | C40: 300 A diesel (engine-driven) | D40: 9500 | E40: 6500 | F40: Per day | G40: 1 day | H40: Engine-driven welder day-hire
A42: Methodology & sources
A43: • WET rate = machine + fuel/power + operator + routine consumables (bits, oil, nozzles). DRY rate = bare equipment hire; customer supplies fuel, power and operator.
A44: • Anchored to published Sri Lankan rental day-rates from Peters Equipment (petersequipment.lk, 2026): generators Rs.4,000–12,000/day by kVA; Rotary Hammer SDS Rs.3,000; Jack Hammer Rs.10,000; Demolition Breaker Rs.4,000; Tamping Rammer Rs.3,500; drills Rs.250–500/day.
A45: • Air compressors, poker/concrete vibrators, submersible & engine water pumps, circular saws and angle grinders are confirmed available for daily hire in the Sri Lankan market (surplus.lk, wedabima.com); where a vendor lists "call for price", the rate shown is a competitive Colombo / Western-Province hire-shop day-rate.
A46: • Rates are indicative for quotation/proforma use and exclude 18% VAT, transport/mobilisation, and any operator overtime. Minimum billing is one (1) day unless agreed otherwise.
A47: • Review the WET/DRY cells (blue/green) each quarter against current market quotes; they are hardcoded inputs, not formulas.

Sheet Summary
A1: FLEET SUMMARY — Counts & Monthly Revenue Potential
A2: Monthly potential = unit count × average monthly WET rate (120 hrs, 85% volume discount) if every machine deployed 1 full month.
A4: # | B4: Category | C4: Unit count | D4: Avg. Hourly WET | E4: Avg. Monthly WET (120h) | F4: Category Monthly Revenue Potential
A5: 1 | B5: Backhoe Loader | C5: 24 | D5: =IFERROR(AVERAGEIF('Fleet Pricing'!B:B,B5,'Fleet Pricing'!H:H),0) -> 3704.5833 | E5: =IFERROR(AVERAGEIF('Fleet Pricing'!B:B,B5,'Fleet Pricing'!L:L),0) -> 377937.5 | F5: =C5*E5 -> 9070500
A6: 2 | B6: Wheel Loader | C6: 9 | D6: =IFERROR(AVERAGEIF('Fleet Pricing'!B:B,B6,'Fleet Pricing'!H:H),0) -> 7097.7778 | E6: =IFERROR(AVERAGEIF('Fleet Pricing'!B:B,B6,'Fleet Pricing'!L:L),0) -> 724055.56 | F6: =C6*E6 -> 6516500
A7: 3 | B7: Truck Mixer | C7: 16 | D7: =IFERROR(AVERAGEIF('Fleet Pricing'!B:B,B7,'Fleet Pricing'!H:H),0) -> 3780.625 | E7: =IFERROR(AVERAGEIF('Fleet Pricing'!B:B,B7,'Fleet Pricing'!L:L),0) -> 385656.25 | F7: =C7*E7 -> 6170500
A8: 4 | B8: Self Loader Mixer | C8: 3 | D8: =IFERROR(AVERAGEIF('Fleet Pricing'!B:B,B8,'Fleet Pricing'!H:H),0) -> 4880 | E8: =IFERROR(AVERAGEIF('Fleet Pricing'!B:B,B8,'Fleet Pricing'!L:L),0) -> 498000 | F8: =C8*E8 -> 1494000
A9: 5 | B9: Static Roller | C9: 19 | D9: =IFERROR(AVERAGEIF('Fleet Pricing'!B:B,B9,'Fleet Pricing'!H:H),0) -> 3602.1053 | E9: =IFERROR(AVERAGEIF('Fleet Pricing'!B:B,B9,'Fleet Pricing'!L:L),0) -> 367421.05 | F9: =C9*E9 -> 6981000
A10: 6 | B10: Vibrating Roller | C10: 72 | D10: =IFERROR(AVERAGEIF('Fleet Pricing'!B:B,B10,'Fleet Pricing'!H:H),0) -> 2716.6667 | E10: =IFERROR(AVERAGEIF('Fleet Pricing'!B:B,B10,'Fleet Pricing'!L:L),0) -> 277083.33 | F10: =C10*E10 -> 19950000
A11: 7 | B11: Pneumatic Roller | C11: 10 | D11: =IFERROR(AVERAGEIF('Fleet Pricing'!B:B,B11,'Fleet Pricing'!H:H),0) -> 2983 | E11: =IFERROR(AVERAGEIF('Fleet Pricing'!B:B,B11,'Fleet Pricing'!L:L),0) -> 304250 | F11: =C11*E11 -> 3042500
A12: 8 | B12: Motor Grader | C12: 16 | D12: =IFERROR(AVERAGEIF('Fleet Pricing'!B:B,B12,'Fleet Pricing'!H:H),0) -> 7094.375 | E12: =IFERROR(AVERAGEIF('Fleet Pricing'!B:B,B12,'Fleet Pricing'!L:L),0) -> 723593.75 | F12: =C12*E12 -> 11577500
A13: 9 | B13: Skid Steer | C13: 25 | D13: =IFERROR(AVERAGEIF('Fleet Pricing'!B:B,B13,'Fleet Pricing'!H:H),0) -> 2489.6 | E13: =IFERROR(AVERAGEIF('Fleet Pricing'!B:B,B13,'Fleet Pricing'!L:L),0) -> 254000 | F13: =C13*E13 -> 6350000
A14: 10 | B14: Asphalt Paver | C14: 11 | D14: =IFERROR(AVERAGEIF('Fleet Pricing'!B:B,B14,'Fleet Pricing'!H:H),0) -> 6381.8182 | E14: =IFERROR(AVERAGEIF('Fleet Pricing'!B:B,B14,'Fleet Pricing'!L:L),0) -> 650863.64 | F14: =C14*E14 -> 7159500
A15: 11 | B15: Bitumen Bowser | C15: 4 | D15: =IFERROR(AVERAGEIF('Fleet Pricing'!B:B,B15,'Fleet Pricing'!H:H),0) -> 2747.5 | E15: =IFERROR(AVERAGEIF('Fleet Pricing'!B:B,B15,'Fleet Pricing'!L:L),0) -> 280125 | F15: =C15*E15 -> 1120500
A16: 12 | B16: Mobile Crane | C16: 2 | D16: =IFERROR(AVERAGEIF('Fleet Pricing'!B:B,B16,'Fleet Pricing'!H:H),0) -> 5100 | E16: =IFERROR(AVERAGEIF('Fleet Pricing'!B:B,B16,'Fleet Pricing'!L:L),0) -> 520000 | F16: =C16*E16 -> 1040000
... A33: 29 | B33: Forklift | C33: 3 | D33: =IFERROR(AVERAGEIF('Fleet Pricing'!B:B,B33,'Fleet Pricing'!H:H),0) -> 1770 | E33: =IFERROR(AVERAGEIF('Fleet Pricing'!B:B,B33,'Fleet Pricing'!L:L),0) -> 180500 | F33: =C33*E33 -> 541500
B34: TOTAL FLEET | C34: =SUM(C5:C33) -> 518 | F34: =SUM(F5:F33) -> 159304500

Sheet Fleet Pricing
A1: FLEET PRICING 2026 — ALL 518 UNITS (engineered rates)
A2: Rates in LKR, excluding 18% VAT. Daily min. 4 hrs • Monthly min. 120 hrs. Driven by Rate Card sheet.
A4: # | B4: Category | C4: Brand | D4: E&C No. | E4: Model | F4: Year | G4: Registration No. | H4: Hourly WET | I4: Hourly DRY | J4: Daily WET (4h) | K4: Daily DRY (4h) | L4: Monthly WET (120h) | M4: Monthly DRY (120h) | N4: Remarks | O4: age_f | P4: size_m
A5: BACKHOE LOADER
A6: 1 | B6: Backhoe Loader | C6: BOB CAT | D6: LB-22 | E6: B760 | F6: 2021 | G6: ZB-2586 | H6: =MROUND('Rate Card'!$I$5*O6*P6,10) -> 4150 | I6: =MROUND('Rate Card'!$K$5*O6*P6,10) -> 2000 | J6: =MROUND(H6*4*'Rate Card'!$B$47,100) -> 15800 | K6: =MROUND(I6*4*'Rate Card'!$B$47,100) -> 7600 | L6: =MROUND(H6*120*'Rate Card'!$B$48,500) -> 423500 | M6: =MROUND(I6*120*'Rate Card'!$B$48,500) -> 204000 | O6: 1 | P6: 1
A7: 2 | B7: Backhoe Loader | C7: BOB CAT | D7: LB-23 | E7: B760 | F7: 2021 | G7: ZB-2587 | H7: =MROUND('Rate Card'!$I$5*O7*P7,10) -> 4150 | I7: =MROUND('Rate Card'!$K$5*O7*P7,10) -> 2000 | J7: =MROUND(H7*4*'Rate Card'!$B$47,100) -> 15800 | K7: =MROUND(I7*4*'Rate Card'!$B$47,100) -> 7600 | L7: =MROUND(H7*120*'Rate Card'!$B$48,500) -> 423500 | M7: =MROUND(I7*120*'Rate Card'!$B$48,500) -> 204000 | O7: 1 | P7: 1
A8: 3 | B8: Backhoe Loader | C8: BOB CAT | D8: LB-24 | E8: B760 | F8: 2021 | G8: ZB-2583 | H8: =MROUND('Rate Card'!$I$5*O8*P8,10) -> 4150 | I8: =MROUND('Rate Card'!$K$5*O8*P8,10) -> 2000 | J8: =MROUND(H8*4*'Rate Card'!$B$47,100) -> 15800 | K8: =MROUND(I8*4*'Rate Card'!$B$47,100) -> 7600 | L8: =MROUND(H8*120*'Rate Card'!$B$48,500) -> 423500 | M8: =MROUND(I8*120*'Rate Card'!$B$48,500) -> 204000 | O8: 1 | P8: 1
A9: 4 | B9: Backhoe Loader | C9: J.C.B | D9: LB-16 | E9: 3DX | F9: 2020 | G9: ZB-1547 | H9: =MROUND('Rate Card'!$I$5*O9*P9,10) -> 4150 | I9: =MROUND('Rate Card'!$K$5*O9*P9,10) -> 2000 | J9: =MROUND(H9*4*'Rate Card'!$B$47,100) -> 15800 | K9: =MROUND(I9*4*'Rate Card'!$B$47,100) -> 7600 | L9: =MROUND(H9*120*'Rate Card'!$B$48,500) -> 423500 | M9: =MROUND(I9*120*'Rate Card'!$B$48,500) -> 204000 | O9: 1 | P9: 1
A10: 5 | B10: Backhoe Loader | C10: JCB | D10: LB-02 | E10: 3DX | F10: 2012 | G10: ZA-2963 | H10: =MROUND('Rate Card'!$I$5*O10*P10,10) -> 4150 | I10: =MROUND('Rate Card'!$K$5*O10*P10,10) -> 2000 | J10: =MROUND(H10*4*'Rate Card'!$B$47,100) -> 15800 | K10: =MROUND(I10*4*'Rate Card'!$B$47,100) -> 7600 | L10: =MROUND(H10*120*'Rate Card'!$B$48,500) -> 423500 | M10: =MROUND(I10*120*'Rate Card'!$B$48,500) -> 204000 | O10: 1 | P10: 1
A11: 6 | B11: Backhoe Loader | C11: JCB | D11: LB-03 | E11: 3DX | F11: 2012 | G11: ZA-2964 | H11: =MROUND('Rate Card'!$I$5*O11*P11,10) -> 4150 | I11: =MROUND('Rate Card'!$K$5*O11*P11,10) -> 2000 | J11: =MROUND(H11*4*'Rate Card'!$B$47,100) -> 15800 | K11: =MROUND(I11*4*'Rate Card'!$B$47,100) -> 7600 | L11: =MROUND(H11*120*'Rate Card'!$B$48,500) -> 423500 | M11: =MROUND(I11*120*'Rate Card'!$B$48,500) -> 204000 | O11: 1 | P11: 1
A12: 7 | B12: Backhoe Loader | C12: JCB | D12: LB-09 | E12: 3DX | F12: 2015 | G12: ZA-6069 | H12: =MROUND('Rate Card'!$I$5*O12*P12,10) -> 4150 | I12: =MROUND('Rate Card'!$K$5*O12*P12,10) -> 2000 | J12: =MROUND(H12*4*'Rate Card'!$B$47,100) -> 15800 | K12: =MROUND(I12*4*'Rate Card'!$B$47,100) -> 7600 | L12: =MROUND(H12*120*'Rate Card'!$B$48,500) -> 423500 | M12: =MROUND(I12*120*'Rate Card'!$B$48,500) -> 204000 | O12: 1 | P12: 1
A13: 8 | B13: Backhoe Loader | C13: JCB | D13: LB-11 | E13: 3DX | F13: 2016 | G13: ZA-7092 | H13: =MROUND('Rate Card'!$I$5*O13*P13,10) -> 4150 | I13: =MROUND('Rate Card'!$K$5*O13*P13,10) -> 2000 | J13: =MROUND(H13*4*'Rate Card'!$B$47,100) -> 15800 | K13: =MROUND(I13*4*'Rate Card'!$B$47,100) -> 7600 | L13: =MROUND(H13*120*'Rate Card'!$B$48,500) -> 423500 | M13: =MROUND(I13*120*'Rate Card'!$B$48,500) -> 204000 | O13: 1 | P13: 1
A14: 9 | B14: Backhoe Loader | C14: JCB | D14: LB-13 | E14: 3DX | F14: 2016 | G14: ZA-7965 | H14: =MROUND('Rate Card'!$I$5*O14*P14,10) -> 4150 | I14: =MROUND('Rate Card'!$K$5*O14*P14,10) -> 2000 | J14: =MROUND(H14*4*'Rate Card'!$B$47,100) -> 15800 | K14: =MROUND(I14*4*'Rate Card'!$B$47,100) -> 7600 | L14: =MROUND(H14*120*'Rate Card'!$B$48,500) -> 423500 | M14: =MROUND(I14*120*'Rate Card'!$B$48,500) -> 204000 | O14: 1 | P14: 1
A15: 10 | B15: Backhoe Loader | C15: J.C.B | D15: LB-15 | E15: 570ST | F15: 2019 | G15: ZB-1047 | H15: =MROUND('Rate Card'!$I$5*O15*P15,10) -> 3820 | I15: =MROUND('Rate Card'!$K$5*O15*P15,10) -> 1840 | J15: =MROUND(H15*4*'Rate Card'!$B$47,100) -> 14500 | K15: =MROUND(I15*4*'Rate Card'!$B$47,100) -> 7000 | L15: =MROUND(H15*120*'Rate Card'!$B$48,500) -> 389500 | M15: =MROUND(I15*120*'Rate Card'!$B$48,500) -> 187500 | O15: 0.92 | P15: 1
A16: 11 | B16: Backhoe Loader | C16: JCB | D16: LB-10 | E16: JCB 3DX | F16: 2016 | G16: ZA-7034 | H16: =MROUND('Rate Card'!$I$5*O16*P16,10) -> 3820 | I16: =MROUND('Rate Card'!$K$5*O16*P16,10) -> 1840 | J16: =MROUND(H16*4*'Rate Card'!$B$47,100) -> 14500 | K16: =MROUND(I16*4*'Rate Card'!$B$47,100) -> 7000 | L16: =MROUND(H16*120*'Rate Card'!$B$48,500) -> 389500 | M16: =MROUND(I16*120*'Rate Card'!$B$48,500) -> 187500 | O16: 0.92 | P16: 1
A17: 12 | B17: Backhoe Loader | C17: JCB | D17: LB-14 | E17: JCB 3DX | F17: 2016 | G17: ZA-7968 | H17: =MROUND('Rate Card'!$I$5*O17*P17,10) -> 3820 | I17: =MROUND('Rate Card'!$K$5*O17*P17,10) -> 1840 | J17: =MROUND(H17*4*'Rate Card'!$B$47,100) -> 14500 | K17: =MROUND(I17*4*'Rate Card'!$B$47,100) -> 7000 | L17: =MROUND(H17*120*'Rate Card'!$B$48,500) -> 389500 | M17: =MROUND(I17*120*'Rate Card'!$B$48,500) -> 187500 | O17: 0.92 | P17: 1
... A25: 20 | B25: Backhoe Loader | C25: J.C.B | D25: LB-21 | E25: 3DX | F25: 2020 | G25: ZB-1980 | H25: =MROUND('Rate Card'!$I$5*O25*P25,10) -> 3400 | I25: =MROUND('Rate Card'!$K$5*O25*P25,10) -> 1640 | J25: =MROUND(H25*4*'Rate Card'!$B$47,100) -> 12900 | K25: =MROUND(I25*4*'Rate Card'!$B$47,100) -> 6200 | L25: =MROUND(H25*120*'Rate Card'!$B$48,500) -> 347000 | M25: =MROUND(I25*120*'Rate Card'!$B$48,500) -> 167500 | O25: 0.82 | P25: 1
A26: 21 | B26: Backhoe Loader | C26: JCB | D26: LB-05 | E26: 3DX | F26: 2006 | G26: RS-0483 | H26: =MROUND('Rate Card'!$I$5*O26*P26,10) -> 2990 | I26: =MROUND('Rate Card'!$K$5*O26*P26,10) -> 1440 | J26: =MROUND(H26*4*'Rate Card'!$B$47,100) -> 11400 | K26: =MROUND(I26*4*'Rate Card'!$B$47,100) -> 5500 | L26: =MROUND(H26*120*'Rate Card'!$B$48,500) -> 305000 | M26: =MROUND(I26*120*'Rate Card'!$B$48,500) -> 147000 | N26: age factor 72% | O26: 0.72 | P26: 1
A27: 22 | B27: Backhoe Loader | C27: JCB | D27: LB-07 | E27: JCB 3CX | F27: 2004 | G27: ZA-2608 | H27: =MROUND('Rate Card'!$I$5*O27*P27,10) -> 2700 | I27: =MROUND('Rate Card'!$K$5*O27*P27,10) -> 1300 | J27: =MROUND(H27*4*'Rate Card'!$B$47,100) -> 10300 | K27: =MROUND(I27*4*'Rate Card'!$B$47,100) -> 4900 | L27: =MROUND(H27*120*'Rate Card'!$B$48,500) -> 275500 | M27: =MROUND(I27*120*'Rate Card'!$B$48,500) -> 132500 | N27: age factor 65% | O27: 0.65 | P27: 1
A28: 23 | B28: Backhoe Loader | C28: JCB | D28: LB-06 | E28: 3CX | F28: 2002 | G28: ZA-0447 | H28: =MROUND('Rate Card'!$I$5*O28*P28,10) -> 2700 | I28: =MROUND('Rate Card'!$K$5*O28*P28,10) -> 1300 | J28: =MROUND(H28*4*'Rate Card'!$B$47,100) -> 10300 | K28: =MROUND(I28*4*'Rate Card'!$B$47,100) -> 4900 | L28: =MROUND(H28*120*'Rate Card'!$B$48,500) -> 275500 | M28: =MROUND(I28*120*'Rate Card'!$B$48,500) -> 132500 | N28: age factor 65% | O28: 0.65 | P28: 1
A29: 24 | B29: Backhoe Loader | C29: JCB | D29: LB-04 | E29: SLP3CX | F29: 1999 | G29: RS-0401 | H29: =MROUND('Rate Card'!$I$5*O29*P29,10) -> 2410 | I29: =MROUND('Rate Card'!$K$5*O29*P29,10) -> 1160 | J29: =MROUND(H29*4*'Rate Card'!$B$47,100) -> 9200 | K29: =MROUND(I29*4*'Rate Card'!$B$47,100) -> 4400 | L29: =MROUND(H29*120*'Rate Card'!$B$48,500) -> 246000 | M29: =MROUND(I29*120*'Rate Card'!$B$48,500) -> 118500 | N29: age factor 57% | O29: 0.58 | P29: 1
A30: WHEEL LOADER
A31: 25 | B31: Wheel Loader | C31: SHANTUI | D31: LD-09 | E31: SL-50WN | F31: 2020 | H31: =MROUND('Rate Card'!$I$6*O31*P31,10) -> 8450 | I31: =MROUND('Rate Card'!$K$6*O31*P31,10) -> 3800 | J31: =MROUND(H31*4*'Rate Card'!$B$47,100) -> 32100 | K31: =MROUND(I31*4*'Rate Card'!$B$47,100) -> 14400 | L31: =MROUND(H31*120*'Rate Card'!$B$48,500) -> 862000 | M31: =MROUND(I31*120*'Rate Card'!$B$48,500) -> 387500 | O31: 1 | P31: 1
A32: 26 | B32: Wheel Loader | C32: KOMATSU | D32: LD-07 | E32: WA-80SS | F32: 2015 | H32: =MROUND('Rate Card'!$I$6*O32*P32,10) -> 7770 | I32: =MROUND('Rate Card'!$K$6*O32*P32,10) -> 3500 | J32: =MROUND(H32*4*'Rate Card'!$B$47,100) -> 29500 | K32: =MROUND(I32*4*'Rate Card'!$B$47,100) -> 13300 | L32: =MROUND(H32*120*'Rate Card'!$B$48,500) -> 792500 | M32: =MROUND(I32*120*'Rate Card'!$B$48,500) -> 357000 | O32: 0.92 | P32: 1
A33: 27 | B33: Wheel Loader | C33: KOMATSU | D33: LD-05 | E33: WA150 | F33: 2014 | H33: =MROUND('Rate Card'!$I$6*O33*P33,10) -> 6930 | I33: =MROUND('Rate Card'!$K$6*O33*P33,10) -> 3120 | J33: =MROUND(H33*4*'Rate Card'!$B$47,100) -> 26300 | K33: =MROUND(I33*4*'Rate Card'!$B$47,100) -> 11900 | L33: =MROUND(H33*120*'Rate Card'!$B$48,500) -> 707000 | M33: =MROUND(I33*120*'Rate Card'!$B$48,500) -> 318000 | O33: 0.82 | P33: 1
A34: 28 | B34: Wheel Loader | C34: SANTUI | D34: LD-08 | E34: SL30W | F34: 2014 | H34: =MROUND('Rate Card'!$I$6*O34*P34,10) -> 6930 | I34: =MROUND('Rate Card'!$K$6*O34*P34,10) -> 3120 | J34: =MROUND(H34*4*'Rate Card'!$B$47,100) -> 26300 | K34: =MROUND(I34*4*'Rate Card'!$B$47,100) -> 11900 | L34: =MROUND(H34*120*'Rate Card'!$B$48,500) -> 707000 | M34: =MROUND(I34*120*'Rate Card'!$B$48,500) -> 318000 | O34: 0.82 | P34: 1
A35: 29 | B35: Wheel Loader | C35: KOMATSU | D35: LD-04 | E35: 924F | F35: 2013 | H35: =MROUND('Rate Card'!$I$6*O35*P35,10) -> 6930 | I35: =MROUND('Rate Card'!$K$6*O35*P35,10) -> 3120 | J35: =MROUND(H35*4*'Rate Card'!$B$47,100) -> 26300 | K35: =MROUND(I35*4*'Rate Card'!$B$47,100) -> 11900 | L35: =MROUND(H35*120*'Rate Card'!$B$48,500) -> 707000 | M35: =MROUND(I35*120*'Rate Card'!$B$48,500) -> 318000 | O35: 0.82 | P35: 1
A36: 30 | B36: Wheel Loader | C36: KOMATSU | D36: LD-06 | E36: 510 | F36: 2013 | G36: ZA-3116 | H36: =MROUND('Rate Card'!$I$6*O36*P36,10) -> 6930 | I36: =MROUND('Rate Card'!$K$6*O36*P36,10) -> 3120 | J36: =MROUND(H36*4*'Rate Card'!$B$47,100) -> 26300 | K36: =MROUND(I36*4*'Rate Card'!$B$47,100) -> 11900 | L36: =MROUND(H36*120*'Rate Card'!$B$48,500) -> 707000 | M36: =MROUND(I36*120*'Rate Card'!$B$48,500) -> 318000 | O36: 0.82 | P36: 1
A37: 31 | B37: Wheel Loader | C37: KOMATSU | D37: LD-03 | E37: WA100 | F37: 2012 | H37: =MROUND('Rate Card'!$I$6*O37*P37,10) -> 6930 | I37: =MROUND('Rate Card'!$K$6*O37*P37,10) -> 3120 | J37: =MROUND(H37*4*'Rate Card'!$B$47,100) -> 26300 | K37: =MROUND(I37*4*'Rate Card'!$B$47,100) -> 11900 | L37: =MROUND(H37*120*'Rate Card'!$B$48,500) -> 707000 | M37: =MROUND(I37*120*'Rate Card'!$B$48,500) -> 318000 | O37: 0.82 | P37: 1
A38: 32 | B38: Wheel Loader | C38: CAT | D38: LD-02 | E38: CAT910 | F38: 2010 | H38: =MROUND('Rate Card'!$I$6*O38*P38,10) -> 6930 | I38: =MROUND('Rate Card'!$K$6*O38*P38,10) -> 3120 | J38: =MROUND(H38*4*'Rate Card'!$B$47,100) -> 26300 | K38: =MROUND(I38*4*'Rate Card'!$B$47,100) -> 11900 | L38: =MROUND(H38*120*'Rate Card'!$B$48,500) -> 707000 | M38: =MROUND(I38*120*'Rate Card'!$B$48,500) -> 318000 | O38: 0.82 | P38: 1
A39: 33 | B39: Wheel Loader | C39: CAT | D39: LD-01 | E39: 910E | F39: 2009 | H39: =MROUND('Rate Card'!$I$6*O39*P39,10) -> 6080 | I39: =MROUND('Rate Card'!$K$6*O39*P39,10) -> 2740 | J39: =MROUND(H39*4*'Rate Card'!$B$47,100) -> 23100 | K39: =MROUND(I39*4*'Rate Card'!$B$47,100) -> 10400 | L39: =MROUND(H39*120*'Rate Card'!$B$48,500) -> 620000 | M39: =MROUND(I39*120*'Rate Card'!$B$48,500) -> 279500 | N39: age factor 72% | O39: 0.72 | P39: 1
A40: TRUCK MIXER
A41: 34 | B41: Truck Mixer | C41: TATA | D41: TM-18 | E41: LPK 1618 | F41: 2017 | G41: ZA-8511 | H41: =MROUND('Rate Card'!$I$7*O41*P41,10) -> 4460 | I41: =MROUND('Rate Card'!$K$7*O41*P41,10) -> 2250 | J41: =MROUND(H41*4*'Rate Card'!$B$47,100) -> 16900 | K41: =MROUND(I41*4*'Rate Card'!$B$47,100) -> 8600 | L41: =MROUND(H41*120*'Rate Card'!$B$48,500) -> 455000 | M41: =MROUND(I41*120*'Rate Card'!$B$48,500) -> 229500 | O41: 0.92 | P41: 1
A42: 35 | B42: Truck Mixer | C42: TATA | D42: TM-19 | E42: LPK 2518 | F42: 2017 | G42: ZA-8445 | H42: =MROUND('Rate Card'!$I$7*O42*P42,10) -> 4460 | I42: =MROUND('Rate Card'!$K$7*O42*P42,10) -> 2250 | J42: =MROUND(H42*4*'Rate Card'!$B$47,100) -> 16900 | K42: =MROUND(I42*4*'Rate Card'!$B$47,100) -> 8600 | L42: =MROUND(H42*120*'Rate Card'!$B$48,500) -> 455000 | M42: =MROUND(I42*120*'Rate Card'!$B$48,500) -> 229500 | O42: 0.92 | P42: 1
A43: 36 | B43: Truck Mixer | C43: TATA | D43: TM-15 | E43: LPK 1618 | F43: 2016 | G43: ZA-7925 | H43: =MROUND('Rate Card'!$I$7*O43*P43,10) -> 4460 | I43: =MROUND('Rate Card'!$K$7*O43*P43,10) -> 2250 | J43: =MROUND(H43*4*'Rate Card'!$B$47,100) -> 16900 | K43: =MROUND(I43*4*'Rate Card'!$B$47,100) -> 8600 | L43: =MROUND(H43*120*'Rate Card'!$B$48,500) -> 455000 | M43: =MROUND(I43*120*'Rate Card'!$B$48,500) -> 229500 | O43: 0.92 | P43: 1
A44: 37 | B44: Truck Mixer | C44: ELCHER | D44: TM-11 | E44: TERRA 16 | F44: 2016 | G44: ZA-7291 | H44: =MROUND('Rate Card'!$I$7*O44*P44,10) -> 4460 | I44: =MROUND('Rate Card'!$K$7*O44*P44,10) -> 2250 | J44: =MROUND(H44*4*'Rate Card'!$B$47,100) -> 16900 | K44: =MROUND(I44*4*'Rate Card'!$B$47,100) -> 8600 | L44: =MROUND(H44*120*'Rate Card'!$B$48,500) -> 455000 | M44: =MROUND(I44*120*'Rate Card'!$B$48,500) -> 229500 | O44: 0.92 | P44: 1
A45: 38 | B45: Truck Mixer | C45: ELCHER | D45: TM-12 | E45: TERRA 16 | F45: 2016 | G45: ZA-7290 | H45: =MROUND('Rate Card'!$I$7*O45*P45,10) -> 4460 | I45: =MROUND('Rate Card'!$K$7*O45*P45,10) -> 2250 | J45: =MROUND(H45*4*'Rate Card'!$B$47,100) -> 16900 | K45: =MROUND(I45*4*'Rate Card'!$B$47,100) -> 8600 | L45: =MROUND(H45*120*'Rate Card'!$B$48,500) -> 455000 | M45: =MROUND(I45*120*'Rate Card'!$B$48,500) -> 229500 | O45: 0.92 | P45: 1
A46: 39 | B46: Truck Mixer | C46: TATA | D46: TM-14 | E46: LPK 2518 | F46: 2016 | G46: ZA-7810 | H46: =MROUND('Rate Card'!$I$7*O46*P46,10) -> 4460 | I46: =MROUND('Rate Card'!$K$7*O46*P46,10) -> 2250 | J46: =MROUND(H46*4*'Rate Card'!$B$47,100) -> 16900 | K46: =MROUND(I46*4*'Rate Card'!$B$47,100) -> 8600 | L46: =MROUND(H46*120*'Rate Card'!$B$48,500) -> 455000 | M46: =MROUND(I46*120*'Rate Card'!$B$48,500) -> 229500 | O46: 0.92 | P46: 1
A47: 40 | B47: Truck Mixer | C47: TATA | D47: TM-16 | E47: LPK 2518 | F47: 2016 | G47: ZA-8033 | H47: =MROUND('Rate Card'!$I$7*O47*P47,10) -> 4460 | I47: =MROUND('Rate Card'!$K$7*O47*P47,10) -> 2250 | J47: =MROUND(H47*4*'Rate Card'!$B$47,100) -> 16900 | K47: =MROUND(I47*4*'Rate Card'!$B$47,100) -> 8600 | L47: =MROUND(H47*120*'Rate Card'!$B$48,500) -> 455000 | M47: =MROUND(I47*120*'Rate Card'!$B$48,500) -> 229500 | O47: 0.92 | P47: 1
A48: 41 | B48: Truck Mixer | C48: TATA | D48: TM-21 | E48: LPK 2518 | F48: 2017 | G48: ZA-0050 | H48: =MROUND('Rate Card'!$I$7*O48*P48,10) -> 4460 | I48: =MROUND('Rate Card'!$K$7*O48*P48,10) -> 2250 | J48: =MROUND(H48*4*'Rate Card'!$B$47,100) -> 16900 | K48: =MROUND(I48*4*'Rate Card'!$B$47,100) -> 8600 | L48: =MROUND(H48*120*'Rate Card'!$B$48,500) -> 455000 | M48: =MROUND(I48*120*'Rate Card'!$B$48,500) -> 229500 | O48: 0.92 | P48: 1
...

Sheet Market Research
A1: COMPETITOR PRICE SURVEY — Sri Lanka 2025–2026
A2: Sources: SLLDC (Govt), wedabima.com, krearthmovers, petersequipment.lk, ikman.lk, lankanrentals, boompeek, Tata Motors LK, SENOK, plus Indian rental benchmarks (IndiaMART, Rentkart).
A4: Category | B4: Competitor / Source | C4: Rate (as published) | D4: LKR equivalent | E4: Notes | F4: Our positioning
A5: Backhoe Loader | B5: SLLDC (Govt) – JCB 3CX | C5: Rs. 6,050/h wet | D5: Rs. 6,050/h | E5: Official govt hire rate, with fuel & operator | F5: ~50% below SLLDC
A6: Backhoe Loader | B6: KR Earthmovers (India ref) – JCB 3DX | C6: ₹1,100/h wet / ₹500/h dry | D6: ≈Rs. 3,960/Rs. 1,800 | E6: Monthly Rs.90,000 for 240 hrs | F6: Aligned with regional market
A7: Backhoe Loader | B7: Wedabima – private JCB | C7: Rs. 2,500–3,500/h wet | D7: Rs. 2,500–3,500 | E7: Small Colombo/Gampaha operators | F7: Matching mid-market
A8: Backhoe Loader | B8: Dayani Backhoe Centre | C8: On request | D8: Quote basis | E8: Yakkala/Gampaha district | F8: Our rate is public & transparent
A9: Wheel Loader | B9: SLLDC – Doosan Mega 250 | C9: Rs. 11,390–15,760/h wet | D9: Rs. 11,390–15,760 | E9: 2.0–2.4 cu.m | F9: 30–50% below SLLDC
A10: Wheel Loader | B10: Private SL suppliers | C10: Rs. 5,000–8,000/h | D10: Rs. 5,000–8,000 | E10: Used CAT/Komatsu 910/WA100 | F10: Priced at market mid-point
A11: Truck Mixer | B11: Tantri Lanka | C11: Quote basis | D11: Project-based | E11: Concrete mixer truck supply | F11: Fleet rental differentiator
A12: Truck Mixer | B12: Private SL operators | C12: Rs. 3,500–5,000/h with driver | D12: Rs. 3,500–5,000 | E12: Tata/Ashok Leyland mixers | F12: Competitive
A13: Self Loader Mixer | B13: KR Earthmovers (India ref) | C13: ₹1,500/h wet | D13: ≈Rs. 5,400 | E13: Fiori/Ajax self-loading mixer | F13: Below India rate
A14: Self Loader Mixer | B14: Private SL Fiori | C14: Rs. 4,500–6,000/h | D14: Rs. 4,500–6,000 | E14: 4–8 cu.m self-loader | F14: Aligned
A15: Static Roller | B15: Peters Equipment SL – 1T hand | C15: Rs. 3,500/day | D15: Rs. 3,500/day | E15: Walk-behind 1-ton roller | F15: Matching
... A43: Farm Tractor | B43: Private SL Massey/TAFE | C43: Rs. 1,200–1,800/h | D43: Rs. 1,200–1,800 | E43: 45–75 HP | F43: Mid-market

Sheet Fleet
I1: VEHICLE MACHINERY LISH AT EDWARD AND CHRISTIE | L1: CONVERTED VEHICLE
L2: SOLD
A3: NO | B3: EQUIPMENT DESCRIPTION | C3: E&C NUMBER | D3: BRAND | E3: TYPE OF VEHICLE | F3: MODEL NO | G3: REGISTRATION NO. | H3: CAPACITY | I3: YEAR OF MANUFACTURE | J3: SE.NO | K3: CHASSIS.NO | L3: ENGINE.NO | M3: GPS UNIT | N3: SITE
A4: 1 | B4: BACKHOE LOADER | C4: LB-01 | D4: JCB | E4: Backhoe Loader | F4: 3DX | G4: ZA-2609 | H4: 1.0 cu. m. | I4: 2012 | J4: 1487562 | L4: H00050004 | M4: NO | N4: ALAWWA SITE
A5: 2 | C5: LB-02 | D5: JCB | E5: Backhoe Loader | F5: 3DX | G5: ZA-2963 | H5: 1.0 cu. m. | I5: 2012 | J5: 1487765 | L5: H00032286 | M5: NO | N5: KATANA WATER PROJECT
A6: 3 | C6: LB-03 | D6: JCB | E6: Backhoe Loader | F6: 3DX | G6: ZA-2964 | H6: 1.0 cu. m. | I6: 2012 | J6: 1487793 | L6: H00032137 | M6: NO | N6: KADAWATHA WATER PROJECT
A7: 4 | C7: LB-04 | D7: JCB | E7: Backhoe Loader | F7: SLP3CX | G7: RS-0401 | H7: 1.0 cu. m. | I7: 1999 | J7: SLP3CX7SWE0470373 | L7: AA506060U870023D | M7: NO | N7: AUTO BACS
A8: 5 | C8: LB-05 | D8: JCB | E8: Backhoe Loader | F8: 3DX | G8: RS-0483 | H8: 1.0 cu. m. | I8: 2006 | J8: 1041419 | M8: NO | N8: KATANA WATER PROJECT
A9: 6 | C9: LB-06 | D9: JCB | E9: Backhoe Loader | F9: 3CX | G9: ZA-0447 | H9: 1.0 cu. m. | I9: 2002 | J9: CMT/596/2011/S/P | M9: NO | N9: BADALGAMA
A10: 7 | C10: LB-07 | D10: JCB | E10: Backhoe Loader | F10: JCB 3CX | G10: ZA-2608 | H10: 1.0 cu. m. | I10: 2004 | J10: *0943015 | L10: AK51093U592119K | M10: NO | N10: DORAMADALAWA PLANT
A11: 8 | C11: LB-08 | D11: JCB | E11: Backhoe Loader | F11: JCB 3DX | G11: ZA-6068 | H11: 1.0 cu. m. | I11: 2015 | J11: HAR3DXSUJ01494150 | L11: H00103100 | M11: NO | N11: CENTRAL EXPRESSWAY
A12: 9 | C12: LB-09 | D12: JCB | E12: Backhoe Loader | F12: JCB 3DX | G12: ZA-6069 | H12: 1.0 cu. m. | I12: 2015 | J12: HAR3DXSUE01494156 | L12: H00103915 | M12: NO | N12: GALENBIDUNUWEWA SITE(GALNAWA SITE)
A13: 10 | C13: LB-10 | D13: JCB | E13: Backhoe Loader | F13: JCB 3DX | G13: ZA-7034 | H13: 1.0 cu. m. | I13: 2016 | J13: HAR3DXSUK01497483 | L13: H00121591 | M13: NO | N13: GALNAWA SITE
A14: 11 | C14: LB-11 | D14: JCB | E14: Backhoe Loader | F14: JCB 3DX | G14: ZA-7092 | H14: 1.0 cu. m. | I14: 2016 | J14: HAR3DXSUE01497316 | L14: H000120453 | M14: NO | N14: MIHINTHALE SITE(THALAWA SITE)
A15: 12 | C15: LB-12 | D15: JCB | E15: Backhoe Loader | F15: 3DX | G15: ZA-8337 | H15: 1.0 cu. m. | I15: 2016 | J15: HAR3DXSUC001498720 | L15: H00128304 | M15: NO | N15: AMBANPOLA SITE
A16: 13 | C16: LB-13 | D16: JCB | E16: Backhoe Loader | F16: 3DX | G16: ZA-7965 | H16: 1.0 cu. m. | I16: 2016 | J16: HAR3DXSUJ01499221 | L16: H00130938 | M16: NO | N16: KATANA WATER PROJECT
A17: 14 | C17: LB-14 | D17: JCB | E17: Backhoe Loader | F17: 3DX | G17: ZA-7968 | H17: 1.0 cu. m. | I17: 2016 | J17: HAR3DXSUK01499198 | L17: H00130812 | M17: NO | N17: NOCHCHIYAGAMA SITE(ANU-199)
A18: 15 | C18: LB-15 | D18: J.C.B | E18: Backhoe Loader | F18: 570ST | G18: ZB-1047 | H18: 1.0 cu. m. | I18: 2019 | J18: NKJ570STCKKH00901 | L18: 8045.45.748.265437 | M18: NO | N18: GALENBIDUNUWEWA SITE
A19: 16 | C19: LB-16 | D19: J.C.B | E19: Backhoe Loader | F19: 3DX | G19: ZB-1547 | H19: 1.0 cu. m. | I19: 2020 | J19: HAR3DXSUL02722406 | L19: H00264328 | M19: NO | N19: ALAWWA SITE
A20: 17 | C20: LB-17 | D20: J.C.B | E20: Backhoe Loader | F20: 3DX | G20: ZB-1546 | H20: 1.0 cu. m. | I20: 2020 | J20: HAR3DXSUH02722410 | L20: H00264316 | M20: NO | N20: CHILLOW SITE
A21: 18 | C21: LB-18 | D21: J.C.B | E21: Backhoe Loader | F21: 3DX | G21: ZB-1548 | H21: 1.0 cu. m. | I21: 2020 | J21: HAR3DXSUH02722407 | L21: H00264525 | M21: NO | N21: MUNDALAMA ESTATE
... A27: 24 | C27: LB-24 | D27: BOB CAT | E27: Backhoe Loader | F27: B760 | G27: ZB-2583 | H27: 1.0 cu. m. | I27: 2021 | J27: DBIB5JDGLL0S11003* | L27: NL84759 | M27: NO | N27: GALENBIDUNUWEWA SITE
A29: 25 | B29: WHEEL LOADER | C29: LD-01 | D29: CAT | E29: Wheel Loader | F29: 910E | H29: 0.5 m3 | I29: 2009 | M29: NO | N29: TR-01 MUTUR
A30: 26 | C30: LD-02 | D30: CAT | E30: Wheel Loader | F30: CAT910 | H30: 0.75 m3 | I30: 2010 | M30: NO | N30: BADALGAMA
A31: 27 | C31: LD-03 | D31: KOMATSU | E31: Wheel Loader | F31: WA100 | H31: 0.75 m3 | I31: 2012 | M31: NO | N31: MIHINTHALE PLANT
A32: 28 | C32: LD-04 | D32: KOMATSU | E32: Wheel Loader | F32: 924F | H32: 0.5 m3 | I32: 2013 | M32: NO | N32: C.COM
A33: 29 | C33: LD-05 | D33: KOMATSU | E33: Wheel Loader | F33: WA150 | H33: 0.75 m3 | I33: 2014 | M33: NO | N33: BADALGAMA
A34: 30 | C34: LD-06 | D34: KOMATSU | E34: Wheel Loader | F34: 510 | G34: ZA-3116 | H34: 0.5 m3 | I34: 2013 | M34: NO | N34: BADALGAMA
A35: 31 | C35: LD-07 | D35: KOMATSU | E35: Wheel Loader | F35: WA-80SS | H35: 0.5 m3 | I35: 2015 | J35: 13297 | M35: NO | N35: MIHINTHALE PLANT
A36: 32 | C36: LD-08 | D36: SANTUI | E36: Wheel Loader | F36: SL30W | H36: 0.75 m3 | I36: 2014 | M36: NO | N36: BADALGAMA
A37: 33 | C37: LD-09 | D37: SHANTUI | E37: Wheel Loader | F37: SL-50WN | H37: 01 m3 | I37: 2020 | M37: NO | N37: WADAKADA
A39: 34 | B39: TRUCK MIXTURES | C39: TM-01 | D39: MITSUBISHI | E39: Truck Mixer | F39: KC-FH217C | G39: LK-5048 | H39: 2 m3 | I39: 1996 | J39: FH217C501291 | K39: FH217C501291 | L39: 6D16.831590 | M39: NO | N39: BADALGAMA
A40: 35 | C40: TM-03 | D40: ISUZU | E40: Truck Mixer | F40: KC-NRR33C20 | G40: LK-5047 | H40: 2 m3 | I40: 1996 | J40: NRR33C2-3001266 | K40: NRR33C2-3001266 | M40: NO | N40: ARAWWALA CONSTRUCTION(WALLAWAYA)
A41: 36 | C41: TM-05 | D41: MITSUBISHI | E41: Truck Mixer | F41: KC-FE517BN | G41: LH-5474 | H41: 1 m3 | I41: 1996 | J41: FE517BN520943 | K41: FE517BN520943 | L41: 4D33.E29583 | M41: NO | N41: BADALGAMA
A42: 37 | C42: TM-04 | D42: ISUZU | E42: Truck Mixer | F42: KK-NRR35C4 FORWARD | G42: LL-0690 | H42: 2 m3 | I42: 2000 | J42: NNR35C47000949 | K42: NNR35C47000949 | L42: 6HL1.313673 | M42: NO | N42: DORAMADALAWA PLANT
A43: 38 | C43: TM-06 | D43: MITSUBISHI | E43: Truck Mixer | F43: U.FE315BN | G43: LH-5475 | H43: 1 m3 | I43: 1991 | J43: FE315BN460526 | K43: FE315BN460526 | L43: 4D32.924436 | M43: NO | N43: BADALGAMA
A44: 39 | C44: TM-10 | D44: ASHOK LEYLAND | E44: Truck Mixer | F44: TUSKER SUPER 1613 | G44: ZA-6395 | H44: 4 m3 | I44: 2015 | J44: MB1ADJJA2FRDL3242 | K44: MB1ADJJA2FRDL3242 | L44: FDHZ403004 | M44: NO | N44: DORAMADALAWA PLANT
A45: 40 | C45: TM-09 | D45: MITSUBISHI | E45: Truck Mixer | F45: KK-FE73EB CANTER | G45: ZA-6255 | H45: 1 m3 | I45: 2003 | J45: FE73EB501255 | K45: FE73EB501255 | L45: 4M51-B12860 | M45: NO | N45: BADALGAMA
A46: 41 | C46: TM-08 | D46: ISUZU | E46: Truck Mixer | F46: KC-NRR33C20 | G46: LJ-8055 | H46: 2 m3 | I46: 1996 | J46: NNR33C23001295 | K46: NNR33C23001295 | L46: 6HH1-211921 | M46: NO | N46: MUTUR TR-01
A47: 42 | C47: TM-11 | D47: ELCHER | E47: Truck Mixer | F47: TERRA 16 | G47: ZA-7291 | H47: 4 m3 | I47: 2016 | J47: MC2K7ERCOGK054478 | K47: MC2K7ERCOGK054478 | L47: E613CDGK111850 | M47: NO | N47: BADALGAMA
...

Sheet Engineering Assumptions
A1: ENGINEERING COST ASSUMPTIONS — 2026
A2: Blue cells = editable inputs. All figures in LKR unless stated.
A4: GLOBAL INPUTS
A5: Auto-diesel price (LKR/L) | B5: 382 | C5: Source: CPC / Lanka IOC, March 2026
A6: Monthly working hours (min) | B6: 120 | C6: Given by management
A7: Daily working hours (min) | B7: 4 | C7: Given by management
A8: Operator rate (LKR/hour) | B8: 650 | C8: Given by management
A9: Operator minimum monthly pay (LKR) | B9: 78000 | C9: Given by management — applies when hours × rate < this
A10: Overhead rate (% on direct cost) | B10: 0.15 | C10: Yard, admin, insurance, transport, depreciation recovery
A11: Gross profit margin (% on total cost) | B11: 0.2 | C11: Management target
A12: Working days per month | B12: 26 | C12: 6-day work week
A13: Annual inflation on parts | B13: 0.08 | C13: Applied when projecting multi-year
A16: CATEGORY ENGINEERING DATA
A17: # | B17: Category | C17: Fuel (L/h) | D17: PM base (LKR/h) | E17: Major-repair base (LKR/h) | F17: Brand-new price (LKR mln) | G17: Service life (yrs) | H17: Reliability / market note | I17: Wet hourly fuel cost (LKR)
A18: 1 | B18: Backhoe Loader | C18: 5.5 | D18: 180 | E18: 220 | F18: 18.5 | G18: 12 | H18: JCB 3DX Plus new ~Rs. 15–18M; strong resale | I18: =C18*'Engineering Assumptions'!$B$5 -> 2101
A19: 2 | B19: Wheel Loader | C19: 13 | D19: 350 | E19: 480 | F19: 42 | G19: 15 | H19: SHANTUI SL50W / CAT 910E ~Rs. 35–55M | I19: =C19*'Engineering Assumptions'!$B$5 -> 4966
A20: 3 | B20: Truck Mixer | C20: 7 | D20: 220 | E20: 280 | F20: 22 | G20: 12 | H20: TATA LPK2518 + mixer ~Rs. 20–25M | I20: =C20*'Engineering Assumptions'!$B$5 -> 2674
A21: 4 | B21: Self Loader Mixer | C21: 8 | D21: 260 | E21: 320 | F21: 28 | G21: 10 | H21: FIORI DB350 new ~Rs. 26–30M, niche machine | I21: =C21*'Engineering Assumptions'!$B$5 -> 3056
A22: 5 | B22: Static Roller | C22: 8 | D22: 230 | E22: 310 | F22: 22 | G22: 15 | H22: HAMM 311D / SAKAI SW-900 ~Rs. 20–28M | I22: =C22*'Engineering Assumptions'!$B$5 -> 3056
A23: 6 | B23: Vibrating Roller | C23: 5 | D23: 180 | E23: 240 | F23: 14 | G23: 12 | H23: BOMAG BW138/Dynapac CC1300 ~Rs. 12–18M | I23: =C23*'Engineering Assumptions'!$B$5 -> 1910
A24: 7 | B24: Pneumatic Roller | C24: 7 | D24: 200 | E24: 270 | F24: 19 | G24: 15 | H24: Dynapac CP201 / SAKAI ~Rs. 18–22M | I24: =C24*'Engineering Assumptions'!$B$5 -> 2674
A25: 8 | B25: Motor Grader | C25: 15 | D25: 420 | E25: 600 | F25: 55 | G25: 18 | H25: SANY STG170 / CAT 140 new ~Rs. 45–65M | I25: =C25*'Engineering Assumptions'!$B$5 -> 5730
A26: 9 | B26: Skid Steer | C26: 4.5 | D26: 160 | E26: 200 | F26: 11 | G26: 10 | H26: BOBCAT S450/S770 new ~Rs. 9–13M | I26: =C26*'Engineering Assumptions'!$B$5 -> 1719
A27: 10 | B27: Asphalt Paver | C27: 12 | D27: 420 | E27: 560 | F27: 48 | G27: 12 | H27: VOLVO P6820 / SUMITOMO HA60 ~Rs. 40–55M | I27: =C27*'Engineering Assumptions'!$B$5 -> 4584
A28: 11 | B28: Bitumen Bowser | C28: 6.5 | D28: 170 | E28: 210 | F28: 14 | G28: 15 | H28: DFAC/Foton chassis + insulated tank ~Rs. 12–16M | I28: =C28*'Engineering Assumptions'!$B$5 -> 2483
A29: 12 | B29: Mobile Crane | C29: 10 | D29: 340 | E29: 480 | F29: 48 | G29: 20 | H29: KOBELCO RK250 25T new ~Rs. 45–55M | I29: =C29*'Engineering Assumptions'!$B$5 -> 3820
... A46: 29 | B46: Forklift | C46: 3.5 | D46: 160 | E46: 210 | F46: 12 | G46: 15 | H46: 3T diesel forklift ~Rs. 10–14M | I46: =C46*'Engineering Assumptions'!$B$5 -> 1337
A49: AGE MULTIPLIERS (how costs escalate with age)
A50: Machine age (yrs) | B50: PM multiplier | C50: Major-repair mult | D50: Rationale
A51: 0 – 5 | B51: 1 | C51: 0.3 | D51: Under warranty / basic service only
